<?xml version="1.0" encoding="utf-8"?>
<robot xmlns:xacro="http://www.ros.org/wiki/xacro" name="leo_rover">

  <xacro:macro name="leo" 
               params="default_antenna:=true
                       rockers_fixed:=false
                       footprint_link:=true
                       link_prefix:=''
                       joint_prefix:=''
                       imu_translation:='0.0628 -0.0314 -0.0393'
                       
                       ">

<!-- <xacro:property name="default_antenna"    value=true />
<xacro:property name="rockers_fixed"    value=true />
<xacro:property name="footprint_link"    value=true />
<xacro:property name="link_prefix"    value="" />
<xacro:property name="joint_prefix"    value="" />
<xacro:property name="default_antenna"    value="" />
<xacro:property name="default_antenna"    value="" /> -->

  <xacro:macro name="rocker_link" params="name">
    <link name="${link_prefix}rocker_${name}_link">
      <inertial>
        <mass value="1.387336"/>
        <origin xyz="0 0.01346 -0.06506"/>
        <inertia
          ixx="0.002956" ixy="-0.000001489324" ixz="-0.000008103407"
          iyy="0.02924"  iyz="0.00007112"
          izz="0.02832"/>
      </inertial>
      <visual>
        <geometry>
          <mesh filename="$(find my_leo)/models/Rocker.dae"/>
        </geometry>
      </visual>
      <collision>
        <geometry>
          <mesh filename="$(find my_leo)/models/Rocker_outline.stl"/>
        </geometry>
      </collision>
    </link>
  </xacro:macro>

  <xacro:macro name="wheel_link" params="name model"> 
    <link name="${link_prefix}wheel_${name}_link">
      <inertial>
        <mass value="0.283642"/>
        <origin xyz="0 0.030026 0"/>
        <inertia
          ixx="0.000391"  ixy="0.00000123962" ixz="5.52582e-7"
          iyy="0.0004716" iyz="-0.000002082042"
          izz="0.000391"/>
      </inertial>
      <visual>
        <geometry>
          <mesh filename="$(find my_leo)/models/Wheel${model}.dae"/>
        </geometry>
      </visual>
      <collision>
        <origin xyz="0 0.04485 0" rpy="${pi/2} 0 0"/>
        <geometry>
          <cylinder radius="0.057" length="0.07"/>
        </geometry>
      </collision>
      <collision>
        <origin xyz="0 0.04485 0" rpy="${pi/2} 0 0"/>
        <geometry>
          <cylinder radius="0.0625" length="0.04"/>
        </geometry>
      </collision>
      <collision>
        <geometry>
          <mesh filename="$(find my_leo)/models/Wheel_outline.stl"/>
        </geometry>
      </collision>
    </link>
  </xacro:macro>

  <!-- LINKS -->
  <xacro:if value="${footprint_link}">
    <link name="${link_prefix}base_footprint"/>
  </xacro:if>

  <link name="${link_prefix}base_link">
    <inertial>
      <mass value="1.584994"/>
      <origin xyz="-0.019662 0.011643 -0.031802"/>
      <inertia
        ixx="0.01042" ixy="0.001177" ixz="-0.0008871"
        iyy="0.01045" iyz="0.0002226"
        izz="0.01817"/>
    </inertial>
    <visual>
      <geometry>
        <mesh filename="$(find my_leo)/models/Chassis.dae"/>
      </geometry>
    </visual>
    <collision>
      <geometry>
        <mesh filename="$(find my_leo)/models/Chassis_outline.stl"/>
      </geometry>
    </collision>
  </link>

  <xacro:rocker_link name="L"/>
  <xacro:rocker_link name="R"/>

  <xacro:wheel_link name="FL" model="A"/>
  <xacro:wheel_link name="RL" model="A"/>
  <xacro:wheel_link name="FR" model="B"/>
  <xacro:wheel_link name="RR" model="B"/>

  <xacro:if value="${default_antenna}">
    <link name="${link_prefix}antenna_link">
      <inertial>
        <mass value="0.001237"/>
        <origin xyz="0 0 0.028828"/>
        <inertia
          ixx="2.5529e-7" ixy="0.0" ixz="0.0"
          iyy="2.5529e-7" iyz="0.0"
          izz="1.354e-8"/>
      </inertial>
      <visual>
        <geometry>
          <mesh filename="$(find my_leo)/models/Antenna.dae"/>
        </geometry>
      </visual>
      <collision>
        <origin xyz="0 0 0.028"/>
        <geometry>
          <cylinder radius="0.0055" length="0.056"/>
        </geometry>
      </collision>
    </link>
  </xacro:if>

  <link name="lidar_link">
    <visual>
      <geometry>
        <cylinder length="0.01" radius="0.03" />
      </geometry>
      <origin rpy="0 0 0" xyz="0 0 0"/>
      <material name="black">
        <color rgba="0.1 0.1 0.1 1"/>
      </material>
    </visual>
    <collision>
      <geometry>
        <cylinder length="0.01" radius="0.03" />
      </geometry>
      <origin rpy="0 0 0" xyz="0 0 0"/>
    </collision>

    <inertial>
      <mass value="0.1"/>
      <inertia ixx="0.0005" ixy="0.0" ixz="0.0" iyy="0.0005" iyz="0.0" izz="0.00045"/>
    </inertial>
  </link>
  <link name="${link_prefix}camera_frame"/>
  <link name="${link_prefix}camera_optical_frame"/>
  <link name="${link_prefix}imu_frame"/>

  <!-- JOINTS -->

  <xacro:if value="${footprint_link}">
    <joint name="${joint_prefix}base_joint" type="fixed">
      <origin xyz="0 0 0.19783" rpy="0 0 0"/>
      <parent link="${link_prefix}base_footprint"/>
      <child link="${link_prefix}base_link"/>
    </joint>
  </xacro:if>

  <xacro:if value="${rockers_fixed}">
    <xacro:property name="rockers_joint_type" value="fixed"/>
  </xacro:if>
  <xacro:unless value="${rockers_fixed}">
    <xacro:property name="rockers_joint_type" value="revolute"/>
  </xacro:unless>

  <joint name="${joint_prefix}rocker_L_joint" type="${rockers_joint_type}">
    <origin xyz="0.00263 0.14167 -0.04731" rpy="0 0 ${pi}"/>
    <parent link="${link_prefix}base_link"/>
    <child link="${link_prefix}rocker_L_link"/>
    <axis xyz="0 1 0"/>
    <limit effort="100.0" lower="-0.24" upper="0.24" velocity="100.0"/>
    <dynamics friction="1.0" damping="0.1"/>
  </joint>

  <joint name="${joint_prefix}rocker_R_joint" type="${rockers_joint_type}">
    <origin xyz="0.00263 -0.14167 -0.04731" rpy="0 0 0"/>
    <parent link="${link_prefix}base_link"/>
    <child link="${link_prefix}rocker_R_link"/>
    <axis xyz="0 1 0"/>
    <limit effort="100.0" lower="-0.24" upper="0.24" velocity="100.0"/>
    <dynamics friction="1.0" damping="0.1"/>
    <mimic joint="rocker_L_joint"/>
  </joint>

  <joint name="${joint_prefix}wheel_FL_joint" type="continuous">
    <origin xyz="-0.15256 -0.08214 -0.08802" rpy="0 0 0"/>
    <parent link="${link_prefix}rocker_L_link"/>
    <child link="${link_prefix}wheel_FL_link"/>
    <axis xyz="0 -1 0"/>
    <limit effort="2.0" velocity="6.0"/>
    <dynamics friction="0.3125" damping="0.1"/>
  </joint>

  <joint name="${joint_prefix}wheel_RL_joint" type="continuous">
    <origin xyz="0.15256 -0.08214 -0.08802" rpy="0 0 0"/>
    <parent link="${link_prefix}rocker_L_link"/>
    <child link="${link_prefix}wheel_RL_link"/>
    <axis xyz="0 -1 0"/>
    <limit effort="2.0" velocity="6.0"/>
    <dynamics friction="0.3125" damping="0.1"/>
  </joint>

  <joint name="${joint_prefix}wheel_FR_joint" type="continuous">
    <origin xyz="0.15256 -0.08214 -0.08802" rpy="0 0 0"/>
    <parent link="${link_prefix}rocker_R_link"/>
    <child link="${link_prefix}wheel_FR_link"/>
    <axis xyz="0 1 0"/>
    <limit effort="2.0" velocity="6.0"/>
    <dynamics friction="0.3125" damping="0.1"/>
  </joint>

  <joint name="${joint_prefix}wheel_RR_joint" type="continuous">
    <origin xyz="-0.15256 -0.08214 -0.08802" rpy="0 0 0"/>
    <parent link="${link_prefix}rocker_R_link"/>
    <child link="${link_prefix}wheel_RR_link"/>
    <axis xyz="0 1 0"/>
    <limit effort="2.0" velocity="6.0"/>
    <dynamics friction="0.3125" damping="0.1"/> 
  </joint>

  <xacro:if value="${default_antenna}">
    <joint name="${joint_prefix}antenna_joint" type="fixed">
      <origin xyz="-0.0052 0.056 -0.0065" rpy="0 0 0"/>
      <parent link="${link_prefix}base_link"/>
      <child link="${link_prefix}antenna_link"/>
    </joint>
  </xacro:if>

  <joint name="${joint_prefix}lidar_joint" type="fixed">
    <origin xyz="0.1 0 0.01" rpy="0 0 0"/>
    <parent link="${link_prefix}base_link"/>
    <child link="lidar_link"/>
  </joint>

  <joint name="${joint_prefix}camera_joint" type="fixed">
    <origin xyz="0.0971 0 -0.0427" rpy="0 0.2094 0"/>
    <parent link="${link_prefix}base_link"/>
    <child link="${link_prefix}camera_frame"/>
  </joint>

  <joint name="${joint_prefix}camera_optical_joint" type="fixed">
    <origin xyz="0 0 0" rpy="-${pi/2} 0.0 -${pi/2}"/>
    <parent link="${link_prefix}camera_frame"/>
    <child link="${link_prefix}camera_optical_frame"/>
  </joint>

  <joint name="${joint_prefix}imu_joint" type="fixed">
    <origin xyz="0.0628 -0.0314 -0.0393" rpy="0 0 0"/>
    <parent link="${link_prefix}base_link"/>
    <child link="${link_prefix}imu_frame"/>
  </joint>

  </xacro:macro>

  <!-- LEO GAZEBO -->

  <xacro:macro name="leo_gazebo">
    <xacro:property name="link_prefix" value=""/>
    <xacro:property name="topic_prefix" value='/model/leo_rover'/>

    <!-- base ODE properties -->
    <gazebo reference="${link_prefix}base_footprint">
      <collision>
        <surface>
          <friction>
            <ode>
              <mu>0.3</mu>
              <mu2>0.3</mu2>
            </ode>
            <bullet>
              <friction>0.3</friction>
              <friction2>0.3</friction2>
              <rolling_friction>0.1</rolling_friction>
            </bullet>
          </friction>
        </surface>
      </collision>
    </gazebo>

    <gazebo reference="${link_prefix}base_link">
      <collision>
        <surface>
          <friction>
            <ode>
              <mu>0.3</mu>
              <mu2>0.3</mu2>
            </ode>
            <bullet>
              <friction>0.3</friction>
              <friction2>0.3</friction2>
              <rolling_friction>0.1</rolling_friction>
            </bullet>
          </friction>
        </surface>
      </collision>
    </gazebo>

    <!-- rocker ODE properties -->
    <gazebo reference="${link_prefix}rocker_L_link">
      <collision>
        <surface>
          <friction>
            <ode>
              <mu>0.3</mu>
              <mu2>0.3</mu2>
            </ode>
            <bullet>
              <friction>0.3</friction>
              <friction2>0.3</friction2>
              <rolling_friction>0.1</rolling_friction>
            </bullet>
          </friction>
        </surface>
      </collision>
    </gazebo>

    <gazebo reference="${link_prefix}rocker_R_link">
      <collision>
        <surface>
          <friction>
            <ode>
              <mu>0.3</mu>
              <mu2>0.3</mu2>
            </ode>
            <bullet>
              <friction>0.3</friction>
              <friction2>0.3</friction2>
              <rolling_friction>0.1</rolling_friction>
            </bullet>
          </friction>
        </surface>
      </collision>
    </gazebo>
    <!-- wheel ODE properties -->
    <gazebo reference="${link_prefix}wheel_FL_link">
      <collision>
        <surface>
          <friction>
            <ode>
              <mu>1</mu>
              <mu2>1</mu2>
              <slip1>0.035</slip1>
              <slip2>0</slip2>
              <fdir1>0 0 1</fdir1>
            </ode>
            <bullet>
              <friction>1</friction>
              <friction2>1</friction2>
              <rolling_friction>0.1</rolling_friction>
            </bullet>
          </friction>
        </surface>
      </collision>
    </gazebo>

    <gazebo reference="${link_prefix}wheel_FR_link">
      <collision>
        <surface>
          <friction>
            <ode>
              <mu>1</mu>
              <mu2>1</mu2>
              <slip1>0.035</slip1>
              <slip2>0</slip2>
              <fdir1>0 0 1</fdir1>
            </ode>
            <bullet>
              <friction>1</friction>
              <friction2>1</friction2>
              <rolling_friction>0.1</rolling_friction>
            </bullet>
          </friction>
        </surface>
      </collision>
    </gazebo>

    <gazebo reference="${link_prefix}wheel_RL_link">
      <collision>
        <surface>
          <friction>
            <ode>
              <mu>1</mu>
              <mu2>1</mu2>
              <slip1>0.035</slip1>
              <slip2>0</slip2>
              <fdir1>0 0 1</fdir1>
            </ode>
            <bullet>
              <friction>1</friction>
              <friction2>1</friction2>
              <rolling_friction>0.1</rolling_friction>
            </bullet>
          </friction>
        </surface>
      </collision>
    </gazebo>

    <gazebo reference="${link_prefix}wheel_RR_link">
      <collision>
        <surface>
          <friction>
            <ode>
              <mu>1</mu>
              <mu2>1</mu2>
              <slip1>0.035</slip1>
              <slip2>0</slip2>
              <fdir1>0 0 1</fdir1>
            </ode>
            <bullet>
              <friction>1</friction>
              <friction2>1</friction2>
              <rolling_friction>0.1</rolling_friction>
            </bullet>
          </friction>
        </surface>
      </collision>
    </gazebo>

    <!-- lidar -->
    <gazebo reference="lidar_link">
      <sensor type="gpu_lidar" name="generic_lidar_sensor">

        <topic>${topic_prefix}/scan</topic>
        <frame_id>lidar_link</frame_id>
        <ignition_frame_id>lidar_link</ignition_frame_id>

        <update_rate>10.0</update_rate>
        <ray>
          <scan>
            <horizontal>
              <samples>512</samples>
              <resolution>1</resolution>
              <min_angle>-${pi*0.75}</min_angle>
              <max_angle>${pi*0.75}</max_angle>
            </horizontal>
          </scan>
          <range>
            <min>0.10</min>
            <max>10.0</max>
            <resolution>0.03</resolution>
          </range>
          <noise>
            <type>gaussian</type>
            <mean>0.0</mean>
            <stddev>0.001</stddev>
          </noise>
        </ray>
        <always_on>1</always_on>
        <visualize>false</visualize>
      </sensor>
      <plugin filename="libignition-gazebo-sensors-system.so" name="ignition::gazebo::systems::Sensors">
        <render_engine>ogre2</render_engine>
      </plugin>
    </gazebo>


    <!-- rocker differential -->

    <gazebo>
      <plugin
        filename="ignition-gazebo-joint-state-publisher-system"
        name="ignition::gazebo::systems::JointStatePublisher">
        <topic>${topic_prefix}/joint_states</topic>
        <!-- <joint_name>wheel_FL_joint</joint_name>
        <joint_name>wheel_FR_joint</joint_name>
        <joint_name>wheel_RL_joint</joint_name>
        <joint_name>wheel_RR_joint</joint_name> -->
      </plugin>
      
    </gazebo>

    <gazebo reference="${link_prefix}imu_frame">
      <sensor type="imu" name="leo_imu_sensor">
        <update_rate>100</update_rate>
        <visualize>true</visualize>
        <topic>${topic_prefix}/imu/data_raw</topic>
        <always_on>1</always_on>
        <ignition_frame_id>${link_prefix}imu_frame</ignition_frame_id>
      </sensor>
      <plugin filename="libignition-gazebo-imu-system.so"
        name="ignition::gazebo::systems::Imu">
        <initial_orientation_as_reference>false</initial_orientation_as_reference>
      </plugin>
    </gazebo>

    <!-- Differential Drive - https://gazebosim.org/api/gazebo/4.5/classignition_1_1gazebo_1_1systems_1_1DiffDrive.html -->
    <gazebo>
      <plugin filename="libignition-gazebo-diff-drive-system.so" name="ignition::gazebo::systems::DiffDrive">
        <!-- Wheel Joints -->
        <left_joint>wheel_FL_joint</left_joint>
        <right_joint>wheel_FR_joint</right_joint>
        <left_joint>wheel_RL_joint</left_joint>
        <right_joint>wheel_RR_joint</right_joint>

        <!-- Kinematics -->
        <wheel_separation>0.358</wheel_separation>
        <wheel_radius>0.0625</wheel_radius>

        <odom_publish_frequency>50</odom_publish_frequency>
        
        <!-- TF Frames -->
        <frame_id>odom</frame_id>
        <child_frame_id>base_footprint</child_frame_id>
        
        <topic>${topic_prefix}/cmd_vel</topic>
        <odom_topic>${topic_prefix}/odometry</odom_topic>
        <tf_topic>${topic_prefix}/tf</tf_topic>
      </plugin>
    </gazebo>


  </xacro:macro>

  <xacro:macro name="leo_sim" 
               params="default_antenna:=true
                       fixed:=false">

    <xacro:property name="link_prefix" value=""/>

    <xacro:leo default_antenna="${default_antenna}"
               rockers_fixed="false"/>

    <xacro:leo_gazebo/>

  </xacro:macro>

</robot>